<?xml version="1.0"?>
<robot name="cart">
  <link name="base_link">
    <visual>
      <geometry>
        <box size="0.3 0.3 0.1" />
      </geometry>
    </visual>
    <inertial>
      <mass value="6"/>
      <inertia ixx="0.2" ixy="0" ixz="0" iyy="0.2" iyz="0.0" izz="0.2"/>
    </inertial>
  </link>

  <link name="left_wheel">
    <visual>
      <geometry>
        <cylinder length = "0.05" radius="0.1"/>
      </geometry>
      <origin rpy="1.57075 1.57075 0"/>
      <material name="black"/>
    </visual>
    <collision>
      <geometry>
        <cylinder length="0.05" radius="0.1"/>
      </geometry>
      <origin rpy="1.57075 1.57075 0"/>
    </collision>
    <inertial>
      <origin rpy="1.57075 1.57075 0"/>
      <mass value="0.3"/>
      <inertia ixx="0.4" ixy="0" ixz="0" iyy="0.4" iyz="0.0" izz="0.2"/>
    </inertial>
  </link>

  <joint name="base_to_left_wheel" type="continuous">
    <parent link="base_link"/>
    <child link="left_wheel"/>
    <axis xyz="0 1 0"/>
    <origin xyz="0 -0.175 0"/>
  </joint>

  <link name="right_wheel">
    <visual>
      <geometry>
        <cylinder length = "0.05" radius="0.1"/>
      </geometry>
      <origin rpy="-1.57075 -1.57075 0"/>
      <material name="black"/>
    </visual>
    <collision>
      <geometry>
        <cylinder length="0.05" radius="0.1"/>
      </geometry>
      <origin rpy="1.57075 1.57075 0"/>
    </collision>
    <inertial>
      <origin rpy="1.57075 1.57075 0"/>
      <mass value="0.3"/>
      <inertia ixx="0.4" ixy="0" ixz="0" iyy="0.4" iyz="0.0" izz="0.2"/>
    </inertial>
  </link>

  <joint name="base_to_right_wheel" type="continuous">
    <parent link="base_link"/>
    <child link="right_wheel"/>
    <axis xyz="0 1 0"/>
    <origin xyz="0 0.175 0"/>
  </joint>
</robot>